							// throw internal exception which will be caught below